<?xml version="1.0"?>
<robot name="Assembly_final">
    <link name="Amphi_body">
        <inertial>
            <origin xyz="-0.16052442455072136 0.03741442159030612 -0.10010897324556092" rpy="0.0 0.0 0.0" />
            <mass value="7.212459883295273" />
            <inertia ixx="0.06506646769772223" iyy="0.13809045817247934" izz="0.10935344623609505" ixy="0.0002686711305598388" iyz="0.0002123059404934846" ixz="-0.00034021188690566695" />
        </inertial>
        <visual name="Amphi_body_visual">
            <origin xyz="0.0 0.0 0" rpy="1.57 0.0 0.0" />
               <material name="blue">
        <color rgba="1 0 1 1"/>
      </material>
            <geometry>
                <mesh filename="package://amphi_description/urdf/meshes/Amphi_body-v14.stl" scale="0.001 0.001 0.001" />
                </geometry>
        </visual>
        <collision name="Amphi_body_collision">
            <origin xyz="0.0 0.0 0.0" rpy="1.57 0.0 0.0" />
            <geometry>
                <mesh filename="package://amphi_description/urdf/meshes/Amphi_body-v14.stl" scale="0.001 0.001 0.001" />
            </geometry>
        </collision>
    </link>

    <!-- LEFT FRONT SUPPORT START -->
    <link name="left-front-support">
        <inertial>
            <origin xyz="0.004300914423757223 -0.04468754891850409 -0.003998080014032616" rpy="0.0 -0.0 0.0" />
            <mass value="0.1258063436309947" />
            <inertia ixx="0.0001501406958340848" iyy="4.3034898065928e-05" izz="0.00019183422148696038" ixy="6.660019146001358e-05" iyz="-1.0768671639301008e-08" ixz="2.9914083973575298e-09" />
        </inertial>
        <visual name="left-front-support_visual">
            <origin xyz="0.0 0.0 0.0" rpy="0.0 0.0 0.0" />
           <!-- <origin xyz="-0.25 -0.01 0.025" rpy="3.14 0.0 3.14" /> -->
           <material name="blue">
        <color rgba="1 0 0 1"/>
      </material>
            <geometry>
            
                <mesh filename="package://amphi_description/urdf/meshes/left-front-support-v6.stl" scale="0.001 0.001 0.001" />
            </geometry>
        </visual>
        <collision name="left-front-support_collision">
            <origin xyz="-0.0 -0.0 0.0 " rpy="0.0 0.0 0.0" />
            <geometry>
                <mesh filename="package://amphi_description/urdf/meshes/left-front-support-v6.stl" scale="0.001 0.001 0.001" />
            </geometry>
        </collision>
    </link>
    <link name="left-back-support">
        <inertial>
            <origin xyz="-0.01450222929112158 -0.043333072190978615 0.021299928839357118" rpy="0.0 -0.0 0.0" />
            <mass value="0.23800029540907736" />
            <inertia ixx="0.0005606859095804067" iyy="7.287013630525446e-05" izz="0.0006027459478643443" ixy="-0.00012661140186572342" iyz="4.8473192240038824e-05" ixz="7.273497099445289e-06" />
        </inertial>
        <visual name="left-back-support_visual">
            <origin xyz="-0.0 0.0 0.0" rpy="0.0 0.0 0.0"/>
                <material name="blue">
        <color rgba="1 0 0 1"/>
      </material>
            <geometry>
                <mesh filename="package://amphi_description/urdf/meshes/left-back-support-v3.stl" scale="0.001 0.001 0.001" />
            </geometry>
        </visual>
        <collision name="left-back-support_collision">
            <origin xyz="-0.0 0.0 0.0" rpy="0.0 0.0 0.0" />
            <geometry>
                <mesh filename="package://amphi_description/urdf/meshes/left-back-support-v3.stl" scale="0.001 0.001 0.001" />
            </geometry>
        </collision>
    </link>
    <!-- LEFT FRONT SUPPORT END -->
    <!-- RIGHT WHEEL SUPPORT START -->
    <link name="right-front-support">
        <inertial>
            <origin xyz="-0.020300914366342973 -0.04468754891850351 -0.003998080040314953" rpy="0.0 -0.0 0.0" />
            <mass value="0.12580634363099644" />
            <inertia ixx="0.00015014069576797275" iyy="4.303489751521922e-05" izz="0.00019183422100238143" ixy="-6.660019137171447e-05" iyz="-1.076862307658466e-08" ixz="-2.991215034345296e-09" />
        </inertial>
        <visual name="right-front-support_visual">
            <origin xyz="0.0 0.0 0.0" rpy="0.0 0.0 0.0" />
        <material name="grey">
        <color rgba="1 0.34 0.2 1"/>
      </material>
            <geometry>
                <mesh filename="package://amphi_description/urdf/meshes/right-front-support-v6.stl" scale="0.001 0.001 0.001" />
            </geometry>
        </visual>
        <collision name="right-front-support_collision">
             <origin xyz="0.0 0.0 0.0" rpy="0.0 0.0 0.0" />
            <geometry>
                <mesh filename="package://amphi_description/urdf/meshes/right-front-support-v6.stl" scale="0.001 0.001 0.001" />
            </geometry>
        </collision>
    </link>
    <link name="right-back-support">
        <inertial>
            <origin xyz="-0.001497770820030162 0.04333307219097929 -0.021299928900500077" rpy="0.0 -0.0 0.0" />
            <mass value="0.23800029540906284" />
            <inertia ixx="0.0005606859100075988" iyy="7.287013855952957e-05" izz="0.0006027459496901894" ixy="-0.00012661140221863383" iyz="4.847319204596815e-05" ixz="7.273496208417098e-06" />
        </inertial>
        <visual name="right-back-support_visual">
            <origin xyz="0.0 0.0 0.0" rpy="0.0 0.0 0.0" />
            <geometry>
                <mesh filename="package://amphi_description/urdf/meshes/right--back-support-v5.stl" scale="0.001 0.001 0.001" />
            </geometry>
                       <material name="blue">
        <color rgba="1 0.34 0.2 1"/>
      </material>
        </visual>
        <collision name="right-back-support_collision">
            <origin xyz="0.0 0.0 0.0" rpy="0.0 0.0 0.0" />
            <geometry>
                <mesh filename="package://amphi_description/urdf/meshes/right--back-support-v5.stl" scale="0.001 0.001 0.001" />
            </geometry>
        </collision>
    </link>
<!-- RIGHT WHEEL SUPPORT END-->

   <!-- WHEEL START -->
    <link name="left-wheel">
        <inertial>
            <origin xyz="9.071930888297047e-05 -0.00014991238285844228 0.11823415122271601" rpy="0.0 0.0 0.0" />
            <mass value="5.030310348521676" />
            <inertia ixx="0.04100577658518084" iyy="0.04099177637825906" izz="0.01414452358314806" ixy="1.3387566296825714e-05" iyz="-2.887732385952568e-05" ixz="-4.805083875256088e-05" />
        </inertial>
        <visual name="left-wheel_visual">
            <origin xyz="0.0 0.0 0.0" rpy="0.0 0.0 0.0" />
            <geometry>
                <mesh filename="package://amphi_description/urdf/meshes/left-wheel-v4.stl" scale="0.001 0.001 0.001" />
            </geometry>
        </visual>
        <collision name="left-wheel_collision">
            <origin xyz="0.0 0.0 0.0" rpy="0.0 0.0 0.0" />
            <geometry>
                <mesh filename="package://amphi_description/urdf/meshes/left-wheel-v4.stl" scale="0.001 0.001 0.001" />
            </geometry>
        </collision>
    </link>
    <link name="right-wheel">
        <inertial>
            <origin xyz="8.981737534367596e-05 0.00014839768795274792 0.11694916102186585" rpy="0.0 0.0 0.0 " />
            <mass value="5.029486679133445" />
            <inertia ixx="0.04099603333746145" iyy="0.04098224129578613" izz="0.014133771445009054" ixy="-1.3196274334909934e-05" iyz="2.858954654001921e-05" ixz="-4.756139133844742e-05" />
        </inertial>
        <visual name="right-wheel_visual">
            <origin xyz="0.0 0.0 0.0" rpy="0.0 0.0 0.0" />
            <geometry>
                <mesh filename="package://amphi_description/urdf/meshes/right-wheel-v5.stl" scale="0.001 0.001 0.001" />
            </geometry>
        </visual>
        <collision name="right-wheel_collision">
            <origin xyz="0.0 0.0 0.0" rpy="0.0 0.0 0.0" />
            <geometry>
                <mesh filename="package://amphi_description/urdf/meshes/right-wheel-v5.stl" scale="0.001 0.001 0.001" />
            </geometry>
        </collision>
    </link>
    <!-- WHEEL END -->
<!-- SHAFT START -->
<link name="shaft-left">
        <inertial>
            <origin xyz="-3.8907946731114865e-09 -0.14400000000000013 2.684804094599258e-09" rpy="0.0 -0.0 0.0" />
            <mass value="0.02841005068494322" />
            <inertia ixx="0.00019639868038501317" iyy="5.682010136964094e-08" izz="0.0001963986803850122" ixy="2.168404344971009e-19" iyz="2.710505431213761e-20" ixz="-1.0842021724855107e-19" />
        </inertial>
        <visual name="shaft-left_visual">
            <origin xyz="-0.0 -0.0 0.0" rpy="0.0 0.0 0.0" />
            <geometry>
                <mesh filename="package://amphi_description/urdf/meshes/shaft-v4.stl" scale="0.001 0.001 0.001" />
            </geometry>
        </visual>
        <collision name="shaft-left_collision">
            <origin xyz="-0.0 0.0 0.0 " rpy="0.0 0.0 0.0" />
            <geometry>
                <mesh filename="package://amphi_description/urdf/meshes/shaft-v4.stl" scale="0.001 0.001 0.001" />
            </geometry>
        </collision>
</link>


<link name="shaft-right">
        <inertial>
            <origin xyz="3.890793704997009e-09 -0.14399999999999946 2.684805586739003e-09" rpy="0.0 -0.0 0.0" />
            <mass value="0.02841005068494322" />
            <inertia ixx="0.00019639868038501306" iyy="5.682010136989844e-08" izz="0.0001963986803850129" ixy="4.867429162901075e-35" iyz="-8.39694617356321e-52" ixz="-3.3881317889973703e-21" />
        </inertial>
        <visual name="shaft-right_visual">
            <origin xyz="0.0 0.0 0.0" rpy="0.0 0.0 0.0" />
            <geometry>
                <mesh filename="package://amphi_description/urdf/meshes/shaft-v4.stl" scale="0.001 0.001 0.001" />
            </geometry>
        </visual>
        <collision name="shaft-right_collision">
            <origin xyz="0.0 0.0 0.0" rpy="0.0 0.0 0.0" />
            <geometry>
                <mesh filename="package://amphi_description/urdf/meshes/shaft-v4.stl" scale="0.001 0.001 0.001" />
            </geometry>
        </collision>
</link>
    <!-- SHAFT END -->

 <joint name="left-front-support-joint" type="fixed" >
<origin xyz="-0.23 -0.009 -0.016" rpy="3.14 0.0 3.14" />
<parent link="Amphi_body" />
<child link="left-front-support" />
</joint>

  


<joint name="shaft-left-joint" type="fixed" >
<origin xyz="0.1 0.01 0.07" rpy="0.0 0.0 3.14"  />
<parent link="left-front-support" />
<child link="shaft-left"/>
</joint>


<joint name="right-front-support-joint" type="fixed" >
<origin xyz="-0.040 -0.029 -0.015" rpy="0.0 3.14 0.0" />
<parent link="Amphi_body" />
<child link="right-front-support" />
</joint>  


<joint name="shaft-right-joint" type="fixed" >
<origin xyz="-0.059 0.03 0.0715" rpy="0.0 0.0 3.14"  />
<parent link="right-front-support" />
<child link="shaft-right"/>
</joint>

<joint name="shaft-left-back-joint" type="fixed" >
<origin xyz="0.06 -0.23 -0.11" rpy="0.0 0.0 0.0"  />
<parent link="shaft-left" />
<child link="left-back-support"/>
</joint>


<joint name="shaft-right-back-joint" type="fixed" >
<origin xyz="-0.1 -0.21 -0.11" rpy="0.0 0.0 0.0"  />
<parent link="shaft-right" />
<child link="right-back-support"/>
</joint>

<joint name="right-wheel-joint"  type="continuous">
<origin xyz="0.0 0.013 0.0" rpy="1.57 0.0 0.0"  />
<parent link="shaft-right" />
<child link="right-wheel"/>
   <axis xyz="0 0  1"/>
</joint>

<joint name="left-wheel-joint" type="continuous" >
<origin xyz="0.0 0.013 0.0" rpy="1.57 0.0 0.0"  />
<parent link="shaft-left" />

<child link="left-wheel"/>
   <axis xyz="0 0  1"/>
</joint>


</robot>
